Workbook

Sheet README
A1: Deliverable 2 — Household Aggregation Workbook (Read-Only Aggregation Layer)
A3: Purpose
A4: This workbook aggregates FINAL, accepted account-level outputs produced by Deliverable 1. It does NOT ingest raw transactions and does NOT perform ACB/FX/tax recomputation.
A6: How to use (3 steps)
A7: 1) Fill in households + accounts on the 'CONFIG' sheet.
A8: 2) Paste or link account-level outputs into 'INPUT_ACCOUNT_SUMMARY' and (optionally) 'INPUT_SECURITY_DETAIL'.
A9: 3) Review household rollups on 'HH_SUMMARY' and drill-down via filters on 'ACCOUNT_ROLLUP' / 'INPUT_SECURITY_DETAIL'.
A11: Reconciliation
A12: See 'CHECKS' for pass/fail comparisons between household totals and summed account totals.

Sheet CONFIG
A1: Configuration
A3: Base Currency | B3: CAD
A4: Period Start | B4: 2025-01-01
A5: Period End | B5: 2025-12-31
A7: Households (enter at least one)
A8: Household_ID | B8: Household_Name | C8: Notes
A31: Accounts (enter each account to be aggregated)
A32: Include | B32: Account_ID | C32: Account_Name | D32: Owner | E32: Household_ID | F32: Base_Currency | G32: Notes
A33: TRUE
A34: TRUE
A35: TRUE
A36: TRUE
A37: TRUE
A38: TRUE
A39: TRUE
A40: TRUE
A41: TRUE
A42: TRUE
A43: TRUE
A44: TRUE
... A232: TRUE

Sheet INPUT_ACCOUNT_SUMMARY
A1: Input: Account-level period outputs (paste from Deliverable 1)
A3: Account_ID | B3: Period_Start | C3: Period_End | D3: Begin_Balance_Base | E3: End_Balance_Base | F3: Net_Contrib_Base | G3: Income_Interest_Base | H3: Income_Dividends_Base | I3: Income_Other_Base | J3: Realized_GL_Base | K3: Fees_Base | L3: Taxes_Base | M3: Return_Period

Sheet INPUT_SECURITY_DETAIL
A1: Optional input: Security-level outputs (for security→account→household drill-down)
A3: Account_ID | B3: AsOfDate | C3: Security_ID | D3: Security_Name | E3: Asset_Class | F3: Currency | G3: Market_Value_Base | H3: Income_Interest_Base | I3: Income_Dividends_Base | J3: Income_Other_Base | K3: Realized_GL_Base | L3: Notes

Sheet ACCOUNT_ROLLUP
A1: Account Rollup (from INPUT_ACCOUNT_SUMMARY)
A3: Account_ID | B3: Account_Name | C3: Household_ID | D3: Begin_Balance_Base | E3: End_Balance_Base | F3: Net_Contrib_Base | G3: Income_Interest_Base | H3: Income_Dividends_Base | I3: Income_Other_Base | J3: Income_Total_Base | K3: Realized_GL_Base | L3: Fees_Base | M3: Taxes_Base | N3: Return_Period
A4: =IFERROR(INDEX(tblAccounts[Account_ID],1),"") | B4: =IF(A4="","",IFERROR(XLOOKUP(A4,tblAccounts[Account_ID],tblAccounts[Account_Name],""),"")) | C4: =IF(A4="","",IFERROR(XLOOKUP(A4,tblAccounts[Account_ID],tblAccounts[Household_ID],""),"")) | D4: =IF(A4="","",IF(IFERROR(XLOOKUP(A4,tblAccounts[Account_ID],tblAccounts[Include],FALSE),FALSE),SUMIFS(tblAcctSummary[Begin_Balance_Base],tblAcctSummary[Account_ID],A4),0)) | E4: =IF(A4="","",IF(IFERROR(XLOOKUP(A4,tblAccounts[Account_ID],tblAccounts[Include],FALSE),FALSE),SUMIFS(tblAcctSummary[End_Balance_Base],tblAcctSummary[Account_ID],A4),0)) | F4: =IF(A4="","",IF(IFERROR(XLOOKUP(A4,tblAccounts[Account_ID],tblAccounts[Include],FALSE),FALSE),SUMIFS(tblAcctSummary[Net_Contrib_Base],tblAcctSummary[Account_ID],A4),0)) | G4: =IF(A4="","",IF(IFERROR(XLOOKUP(A4,tblAccounts[Account_ID],tblAccounts[Include],FALSE),FALSE),SUMIFS(tblAcctSummary[Income_Interest_Base],tblAcctSummary[Account_ID],A4),0)) | H4: =IF(A4="","",IF(IFERROR(XLOOKUP(A4,tblAccounts[Account_ID],tblAccounts[Include],FALSE),FALSE),SUMIFS(tblAcctSummary[Income_Dividends_Base],tblAcctSummary[Account_ID],A4),0)) | I4: =IF(A4="","",IF(IFERROR(XLOOKUP(A4,tblAccounts[Account_ID],tblAccounts[Include],FALSE),FALSE),SUMIFS(tblAcctSummary[Income_Other_Base],tblAcctSummary[Account_ID],A4),0)) | J4: =IF(A4="","",SUM(G4:I4)) | K4: =IF(A4="","",IF(IFERROR(XLOOKUP(A4,tblAccounts[Account_ID],tblAccounts[Include],FALSE),FALSE),SUMIFS(tblAcctSummary[Realized_GL_Base],tblAcctSummary[Account_ID],A4),0)) | L4: =IF(A4="","",IF(IFERROR(XLOOKUP(A4,tblAccounts[Account_ID],tblAccounts[Include],FALSE),FALSE),SUMIFS(tblAcctSummary[Fees_Base],tblAcctSummary[Account_ID],A4),0)) | M4: =IF(A4="","",IF(IFERROR(XLOOKUP(A4,tblAccounts[Account_ID],tblAccounts[Include],FALSE),FALSE),SUMIFS(tblAcctSummary[Taxes_Base],tblAcctSummary[Account_ID],A4),0)) | N4: =IF(A4="","",IF(IFERROR(XLOOKUP(A4,tblAccounts[Account_ID],tblAccounts[Include],FALSE),FALSE),IFERROR(SUMPRODUCT(tblAcctSummary[Return_Period],tblAcctSummary[Begin_Balance_Base],--(tblAcctSummary[Account_ID]=A4))/IF(SUMIFS(tblAcctSummary[Begin_Balance_Base],tblAcctSummary[Account_ID],A4)=0,NA(),SUMIFS(tblAcctSummary[Begin_Balance_Base],tblAcctSummary[Account_ID],A4)),0),0))
A5: =IFERROR(INDEX(tblAccounts[Account_ID],2),"") | B5: =IF(A5="","",IFERROR(XLOOKUP(A5,tblAccounts[Account_ID],tblAccounts[Account_Name],""),"")) | C5: =IF(A5="","",IFERROR(XLOOKUP(A5,tblAccounts[Account_ID],tblAccounts[Household_ID],""),"")) | D5: =IF(A5="","",IF(IFERROR(XLOOKUP(A5,tblAccounts[Account_ID],tblAccounts[Include],FALSE),FALSE),SUMIFS(tblAcctSummary[Begin_Balance_Base],tblAcctSummary[Account_ID],A5),0)) | E5: =IF(A5="","",IF(IFERROR(XLOOKUP(A5,tblAccounts[Account_ID],tblAccounts[Include],FALSE),FALSE),SUMIFS(tblAcctSummary[End_Balance_Base],tblAcctSummary[Account_ID],A5),0)) | F5: =IF(A5="","",IF(IFERROR(XLOOKUP(A5,tblAccounts[Account_ID],tblAccounts[Include],FALSE),FALSE),SUMIFS(tblAcctSummary[Net_Contrib_Base],tblAcctSummary[Account_ID],A5),0)) | G5: =IF(A5="","",IF(IFERROR(XLOOKUP(A5,tblAccounts[Account_ID],tblAccounts[Include],FALSE),FALSE),SUMIFS(tblAcctSummary[Income_Interest_Base],tblAcctSummary[Account_ID],A5),0)) | H5: =IF(A5="","",IF(IFERROR(XLOOKUP(A5,tblAccounts[Account_ID],tblAccounts[Include],FALSE),FALSE),SUMIFS(tblAcctSummary[Income_Dividends_Base],tblAcctSummary[Account_ID],A5),0)) | I5: =IF(A5="","",IF(IFERROR(XLOOKUP(A5,tblAccounts[Account_ID],tblAccounts[Include],FALSE),FALSE),SUMIFS(tblAcctSummary[Income_Other_Base],tblAcctSummary[Account_ID],A5),0)) | J5: =IF(A5="","",SUM(G5:I5)) | K5: =IF(A5="","",IF(IFERROR(XLOOKUP(A5,tblAccounts[Account_ID],tblAccounts[Include],FALSE),FALSE),SUMIFS(tblAcctSummary[Realized_GL_Base],tblAcctSummary[Account_ID],A5),0)) | L5: =IF(A5="","",IF(IFERROR(XLOOKUP(A5,tblAccounts[Account_ID],tblAccounts[Include],FALSE),FALSE),SUMIFS(tblAcctSummary[Fees_Base],tblAcctSummary[Account_ID],A5),0)) | M5: =IF(A5="","",IF(IFERROR(XLOOKUP(A5,tblAccounts[Account_ID],tblAccounts[Include],FALSE),FALSE),SUMIFS(tblAcctSummary[Taxes_Base],tblAcctSummary[Account_ID],A5),0)) | N5: =IF(A5="","",IF(IFERROR(XLOOKUP(A5,tblAccounts[Account_ID],tblAccounts[Include],FALSE),FALSE),IFERROR(SUMPRODUCT(tblAcctSummary[Return_Period],tblAcctSummary[Begin_Balance_Base],--(tblAcctSummary[Account_ID]=A5))/IF(SUMIFS(tblAcctSummary[Begin_Balance_Base],tblAcctSummary[Account_ID],A5)=0,NA(),SUMIFS(tblAcctSummary[Begin_Balance_Base],tblAcctSummary[Account_ID],A5)),0),0))
A6: =IFERROR(INDEX(tblAccounts[Account_ID],3),"") | B6: =IF(A6="","",IFERROR(XLOOKUP(A6,tblAccounts[Account_ID],tblAccounts[Account_Name],""),"")) | C6: =IF(A6="","",IFERROR(XLOOKUP(A6,tblAccounts[Account_ID],tblAccounts[Household_ID],""),"")) | D6: =IF(A6="","",IF(IFERROR(XLOOKUP(A6,tblAccounts[Account_ID],tblAccounts[Include],FALSE),FALSE),SUMIFS(tblAcctSummary[Begin_Balance_Base],tblAcctSummary[Account_ID],A6),0)) | E6: =IF(A6="","",IF(IFERROR(XLOOKUP(A6,tblAccounts[Account_ID],tblAccounts[Include],FALSE),FALSE),SUMIFS(tblAcctSummary[End_Balance_Base],tblAcctSummary[Account_ID],A6),0)) | F6: =IF(A6="","",IF(IFERROR(XLOOKUP(A6,tblAccounts[Account_ID],tblAccounts[Include],FALSE),FALSE),SUMIFS(tblAcctSummary[Net_Contrib_Base],tblAcctSummary[Account_ID],A6),0)) | G6: =IF(A6="","",IF(IFERROR(XLOOKUP(A6,tblAccounts[Account_ID],tblAccounts[Include],FALSE),FALSE),SUMIFS(tblAcctSummary[Income_Interest_Base],tblAcctSummary[Account_ID],A6),0)) | H6: =IF(A6="","",IF(IFERROR(XLOOKUP(A6,tblAccounts[Account_ID],tblAccounts[Include],FALSE),FALSE),SUMIFS(tblAcctSummary[Income_Dividends_Base],tblAcctSummary[Account_ID],A6),0)) | I6: =IF(A6="","",IF(IFERROR(XLOOKUP(A6,tblAccounts[Account_ID],tblAccounts[Include],FALSE),FALSE),SUMIFS(tblAcctSummary[Income_Other_Base],tblAcctSummary[Account_ID],A6),0)) | J6: =IF(A6="","",SUM(G6:I6)) | K6: =IF(A6="","",IF(IFERROR(XLOOKUP(A6,tblAccounts[Account_ID],tblAccounts[Include],FALSE),FALSE),SUMIFS(tblAcctSummary[Realized_GL_Base],tblAcctSummary[Account_ID],A6),0)) | L6: =IF(A6="","",IF(IFERROR(XLOOKUP(A6,tblAccounts[Account_ID],tblAccounts[Include],FALSE),FALSE),SUMIFS(tblAcctSummary[Fees_Base],tblAcctSummary[Account_ID],A6),0)) | M6: =IF(A6="","",IF(IFERROR(XLOOKUP(A6,tblAccounts[Account_ID],tblAccounts[Include],FALSE),FALSE),SUMIFS(tblAcctSummary[Taxes_Base],tblAcctSummary[Account_ID],A6),0)) | N6: =IF(A6="","",IF(IFERROR(XLOOKUP(A6,tblAccounts[Account_ID],tblAccounts[Include],FALSE),FALSE),IFERROR(SUMPRODUCT(tblAcctSummary[Return_Period],tblAcctSummary[Begin_Balance_Base],--(tblAcctSummary[Account_ID]=A6))/IF(SUMIFS(tblAcctSummary[Begin_Balance_Base],tblAcctSummary[Account_ID],A6)=0,NA(),SUMIFS(tblAcctSummary[Begin_Balance_Base],tblAcctSummary[Account_ID],A6)),0),0))
A7: =IFERROR(INDEX(tblAccounts[Account_ID],4),"") | B7: =IF(A7="","",IFERROR(XLOOKUP(A7,tblAccounts[Account_ID],tblAccounts[Account_Name],""),"")) | C7: =IF(A7="","",IFERROR(XLOOKUP(A7,tblAccounts[Account_ID],tblAccounts[Household_ID],""),"")) | D7: =IF(A7="","",IF(IFERROR(XLOOKUP(A7,tblAccounts[Account_ID],tblAccounts[Include],FALSE),FALSE),SUMIFS(tblAcctSummary[Begin_Balance_Base],tblAcctSummary[Account_ID],A7),0)) | E7: =IF(A7="","",IF(IFERROR(XLOOKUP(A7,tblAccounts[Account_ID],tblAccounts[Include],FALSE),FALSE),SUMIFS(tblAcctSummary[End_Balance_Base],tblAcctSummary[Account_ID],A7),0)) | F7: =IF(A7="","",IF(IFERROR(XLOOKUP(A7,tblAccounts[Account_ID],tblAccounts[Include],FALSE),FALSE),SUMIFS(tblAcctSummary[Net_Contrib_Base],tblAcctSummary[Account_ID],A7),0)) | G7: =IF(A7="","",IF(IFERROR(XLOOKUP(A7,tblAccounts[Account_ID],tblAccounts[Include],FALSE),FALSE),SUMIFS(tblAcctSummary[Income_Interest_Base],tblAcctSummary[Account_ID],A7),0)) | H7: =IF(A7="","",IF(IFERROR(XLOOKUP(A7,tblAccounts[Account_ID],tblAccounts[Include],FALSE),FALSE),SUMIFS(tblAcctSummary[Income_Dividends_Base],tblAcctSummary[Account_ID],A7),0)) | I7: =IF(A7="","",IF(IFERROR(XLOOKUP(A7,tblAccounts[Account_ID],tblAccounts[Include],FALSE),FALSE),SUMIFS(tblAcctSummary[Income_Other_Base],tblAcctSummary[Account_ID],A7),0)) | J7: =IF(A7="","",SUM(G7:I7)) | K7: =IF(A7="","",IF(IFERROR(XLOOKUP(A7,tblAccounts[Account_ID],tblAccounts[Include],FALSE),FALSE),SUMIFS(tblAcctSummary[Realized_GL_Base],tblAcctSummary[Account_ID],A7),0)) | L7: =IF(A7="","",IF(IFERROR(XLOOKUP(A7,tblAccounts[Account_ID],tblAccounts[Include],FALSE),FALSE),SUMIFS(tblAcctSummary[Fees_Base],tblAcctSummary[Account_ID],A7),0)) | M7: =IF(A7="","",IF(IFERROR(XLOOKUP(A7,tblAccounts[Account_ID],tblAccounts[Include],FALSE),FALSE),SUMIFS(tblAcctSummary[Taxes_Base],tblAcctSummary[Account_ID],A7),0)) | N7: =IF(A7="","",IF(IFERROR(XLOOKUP(A7,tblAccounts[Account_ID],tblAccounts[Include],FALSE),FALSE),IFERROR(SUMPRODUCT(tblAcctSummary[Return_Period],tblAcctSummary[Begin_Balance_Base],--(tblAcctSummary[Account_ID]=A7))/IF(SUMIFS(tblAcctSummary[Begin_Balance_Base],tblAcctSummary[Account_ID],A7)=0,NA(),SUMIFS(tblAcctSummary[Begin_Balance_Base],tblAcctSummary[Account_ID],A7)),0),0))
A8: =IFERROR(INDEX(tblAccounts[Account_ID],5),"") | B8: =IF(A8="","",IFERROR(XLOOKUP(A8,tblAccounts[Account_ID],tblAccounts[Account_Name],""),"")) | C8: =IF(A8="","",IFERROR(XLOOKUP(A8,tblAccounts[Account_ID],tblAccounts[Household_ID],""),"")) | D8: =IF(A8="","",IF(IFERROR(XLOOKUP(A8,tblAccounts[Account_ID],tblAccounts[Include],FALSE),FALSE),SUMIFS(tblAcctSummary[Begin_Balance_Base],tblAcctSummary[Account_ID],A8),0)) | E8: =IF(A8="","",IF(IFERROR(XLOOKUP(A8,tblAccounts[Account_ID],tblAccounts[Include],FALSE),FALSE),SUMIFS(tblAcctSummary[End_Balance_Base],tblAcctSummary[Account_ID],A8),0)) | F8: =IF(A8="","",IF(IFERROR(XLOOKUP(A8,tblAccounts[Account_ID],tblAccounts[Include],FALSE),FALSE),SUMIFS(tblAcctSummary[Net_Contrib_Base],tblAcctSummary[Account_ID],A8),0)) | G8: =IF(A8="","",IF(IFERROR(XLOOKUP(A8,tblAccounts[Account_ID],tblAccounts[Include],FALSE),FALSE),SUMIFS(tblAcctSummary[Income_Interest_Base],tblAcctSummary[Account_ID],A8),0)) | H8: =IF(A8="","",IF(IFERROR(XLOOKUP(A8,tblAccounts[Account_ID],tblAccounts[Include],FALSE),FALSE),SUMIFS(tblAcctSummary[Income_Dividends_Base],tblAcctSummary[Account_ID],A8),0)) | I8: =IF(A8="","",IF(IFERROR(XLOOKUP(A8,tblAccounts[Account_ID],tblAccounts[Include],FALSE),FALSE),SUMIFS(tblAcctSummary[Income_Other_Base],tblAcctSummary[Account_ID],A8),0)) | J8: =IF(A8="","",SUM(G8:I8)) | K8: =IF(A8="","",IF(IFERROR(XLOOKUP(A8,tblAccounts[Account_ID],tblAccounts[Include],FALSE),FALSE),SUMIFS(tblAcctSummary[Realized_GL_Base],tblAcctSummary[Account_ID],A8),0)) | L8: =IF(A8="","",IF(IFERROR(XLOOKUP(A8,tblAccounts[Account_ID],tblAccounts[Include],FALSE),FALSE),SUMIFS(tblAcctSummary[Fees_Base],tblAcctSummary[Account_ID],A8),0)) | M8: =IF(A8="","",IF(IFERROR(XLOOKUP(A8,tblAccounts[Account_ID],tblAccounts[Include],FALSE),FALSE),SUMIFS(tblAcctSummary[Taxes_Base],tblAcctSummary[Account_ID],A8),0)) | N8: =IF(A8="","",IF(IFERROR(XLOOKUP(A8,tblAccounts[Account_ID],tblAccounts[Include],FALSE),FALSE),IFERROR(SUMPRODUCT(tblAcctSummary[Return_Period],tblAcctSummary[Begin_Balance_Base],--(tblAcctSummary[Account_ID]=A8))/IF(SUMIFS(tblAcctSummary[Begin_Balance_Base],tblAcctSummary[Account_ID],A8)=0,NA(),SUMIFS(tblAcctSummary[Begin_Balance_Base],tblAcctSummary[Account_ID],A8)),0),0))
A9: =IFERROR(INDEX(tblAccounts[Account_ID],6),"") | B9: =IF(A9="","",IFERROR(XLOOKUP(A9,tblAccounts[Account_ID],tblAccounts[Account_Name],""),"")) | C9: =IF(A9="","",IFERROR(XLOOKUP(A9,tblAccounts[Account_ID],tblAccounts[Household_ID],""),"")) | D9: =IF(A9="","",IF(IFERROR(XLOOKUP(A9,tblAccounts[Account_ID],tblAccounts[Include],FALSE),FALSE),SUMIFS(tblAcctSummary[Begin_Balance_Base],tblAcctSummary[Account_ID],A9),0)) | E9: =IF(A9="","",IF(IFERROR(XLOOKUP(A9,tblAccounts[Account_ID],tblAccounts[Include],FALSE),FALSE),SUMIFS(tblAcctSummary[End_Balance_Base],tblAcctSummary[Account_ID],A9),0)) | F9: =IF(A9="","",IF(IFERROR(XLOOKUP(A9,tblAccounts[Account_ID],tblAccounts[Include],FALSE),FALSE),SUMIFS(tblAcctSummary[Net_Contrib_Base],tblAcctSummary[Account_ID],A9),0)) | G9: =IF(A9="","",IF(IFERROR(XLOOKUP(A9,tblAccounts[Account_ID],tblAccounts[Include],FALSE),FALSE),SUMIFS(tblAcctSummary[Income_Interest_Base],tblAcctSummary[Account_ID],A9),0)) | H9: =IF(A9="","",IF(IFERROR(XLOOKUP(A9,tblAccounts[Account_ID],tblAccounts[Include],FALSE),FALSE),SUMIFS(tblAcctSummary[Income_Dividends_Base],tblAcctSummary[Account_ID],A9),0)) | I9: =IF(A9="","",IF(IFERROR(XLOOKUP(A9,tblAccounts[Account_ID],tblAccounts[Include],FALSE),FALSE),SUMIFS(tblAcctSummary[Income_Other_Base],tblAcctSummary[Account_ID],A9),0)) | J9: =IF(A9="","",SUM(G9:I9)) | K9: =IF(A9="","",IF(IFERROR(XLOOKUP(A9,tblAccounts[Account_ID],tblAccounts[Include],FALSE),FALSE),SUMIFS(tblAcctSummary[Realized_GL_Base],tblAcctSummary[Account_ID],A9),0)) | L9: =IF(A9="","",IF(IFERROR(XLOOKUP(A9,tblAccounts[Account_ID],tblAccounts[Include],FALSE),FALSE),SUMIFS(tblAcctSummary[Fees_Base],tblAcctSummary[Account_ID],A9),0)) | M9: =IF(A9="","",IF(IFERROR(XLOOKUP(A9,tblAccounts[Account_ID],tblAccounts[Include],FALSE),FALSE),SUMIFS(tblAcctSummary[Taxes_Base],tblAcctSummary[Account_ID],A9),0)) | N9: =IF(A9="","",IF(IFERROR(XLOOKUP(A9,tblAccounts[Account_ID],tblAccounts[Include],FALSE),FALSE),IFERROR(SUMPRODUCT(tblAcctSummary[Return_Period],tblAcctSummary[Begin_Balance_Base],--(tblAcctSummary[Account_ID]=A9))/IF(SUMIFS(tblAcctSummary[Begin_Balance_Base],tblAcctSummary[Account_ID],A9)=0,NA(),SUMIFS(tblAcctSummary[Begin_Balance_Base],tblAcctSummary[Account_ID],A9)),0),0))
A10: =IFERROR(INDEX(tblAccounts[Account_ID],7),"") | B10: =IF(A10="","",IFERROR(XLOOKUP(A10,tblAccounts[Account_ID],tblAccounts[Account_Name],""),"")) | C10: =IF(A10="","",IFERROR(XLOOKUP(A10,tblAccounts[Account_ID],tblAccounts[Household_ID],""),"")) | D10: =IF(A10="","",IF(IFERROR(XLOOKUP(A10,tblAccounts[Account_ID],tblAccounts[Include],FALSE),FALSE),SUMIFS(tblAcctSummary[Begin_Balance_Base],tblAcctSummary[Account_ID],A10),0)) | E10: =IF(A10="","",IF(IFERROR(XLOOKUP(A10,tblAccounts[Account_ID],tblAccounts[Include],FALSE),FALSE),SUMIFS(tblAcctSummary[End_Balance_Base],tblAcctSummary[Account_ID],A10),0)) | F10: =IF(A10="","",IF(IFERROR(XLOOKUP(A10,tblAccounts[Account_ID],tblAccounts[Include],FALSE),FALSE),SUMIFS(tblAcctSummary[Net_Contrib_Base],tblAcctSummary[Account_ID],A10),0)) | G10: =IF(A10="","",IF(IFERROR(XLOOKUP(A10,tblAccounts[Account_ID],tblAccounts[Include],FALSE),FALSE),SUMIFS(tblAcctSummary[Income_Interest_Base],tblAcctSummary[Account_ID],A10),0)) | H10: =IF(A10="","",IF(IFERROR(XLOOKUP(A10,tblAccounts[Account_ID],tblAccounts[Include],FALSE),FALSE),SUMIFS(tblAcctSummary[Income_Dividends_Base],tblAcctSummary[Account_ID],A10),0)) | I10: =IF(A10="","",IF(IFERROR(XLOOKUP(A10,tblAccounts[Account_ID],tblAccounts[Include],FALSE),FALSE),SUMIFS(tblAcctSummary[Income_Other_Base],tblAcctSummary[Account_ID],A10),0)) | J10: =IF(A10="","",SUM(G10:I10)) | K10: =IF(A10="","",IF(IFERROR(XLOOKUP(A10,tblAccounts[Account_ID],tblAccounts[Include],FALSE),FALSE),SUMIFS(tblAcctSummary[Realized_GL_Base],tblAcctSummary[Account_ID],A10),0)) | L10: =IF(A10="","",IF(IFERROR(XLOOKUP(A10,tblAccounts[Account_ID],tblAccounts[Include],FALSE),FALSE),SUMIFS(tblAcctSummary[Fees_Base],tblAcctSummary[Account_ID],A10),0)) | M10: =IF(A10="","",IF(IFERROR(XLOOKUP(A10,tblAccounts[Account_ID],tblAccounts[Include],FALSE),FALSE),SUMIFS(tblAcctSummary[Taxes_Base],tblAcctSummary[Account_ID],A10),0)) | N10: =IF(A10="","",IF(IFERROR(XLOOKUP(A10,tblAccounts[Account_ID],tblAccounts[Include],FALSE),FALSE),IFERROR(SUMPRODUCT(tblAcctSummary[Return_Period],tblAcctSummary[Begin_Balance_Base],--(tblAcctSummary[Account_ID]=A10))/IF(SUMIFS(tblAcctSummary[Begin_Balance_Base],tblAcctSummary[Account_ID],A10)=0,NA(),SUMIFS(tblAcctSummary[Begin_Balance_Base],tblAcctSummary[Account_ID],A10)),0),0))
A11: =IFERROR(INDEX(tblAccounts[Account_ID],8),"") | B11: =IF(A11="","",IFERROR(XLOOKUP(A11,tblAccounts[Account_ID],tblAccounts[Account_Name],""),"")) | C11: =IF(A11="","",IFERROR(XLOOKUP(A11,tblAccounts[Account_ID],tblAccounts[Household_ID],""),"")) | D11: =IF(A11="","",IF(IFERROR(XLOOKUP(A11,tblAccounts[Account_ID],tblAccounts[Include],FALSE),FALSE),SUMIFS(tblAcctSummary[Begin_Balance_Base],tblAcctSummary[Account_ID],A11),0)) | E11: =IF(A11="","",IF(IFERROR(XLOOKUP(A11,tblAccounts[Account_ID],tblAccounts[Include],FALSE),FALSE),SUMIFS(tblAcctSummary[End_Balance_Base],tblAcctSummary[Account_ID],A11),0)) | F11: =IF(A11="","",IF(IFERROR(XLOOKUP(A11,tblAccounts[Account_ID],tblAccounts[Include],FALSE),FALSE),SUMIFS(tblAcctSummary[Net_Contrib_Base],tblAcctSummary[Account_ID],A11),0)) | G11: =IF(A11="","",IF(IFERROR(XLOOKUP(A11,tblAccounts[Account_ID],tblAccounts[Include],FALSE),FALSE),SUMIFS(tblAcctSummary[Income_Interest_Base],tblAcctSummary[Account_ID],A11),0)) | H11: =IF(A11="","",IF(IFERROR(XLOOKUP(A11,tblAccounts[Account_ID],tblAccounts[Include],FALSE),FALSE),SUMIFS(tblAcctSummary[Income_Dividends_Base],tblAcctSummary[Account_ID],A11),0)) | I11: =IF(A11="","",IF(IFERROR(XLOOKUP(A11,tblAccounts[Account_ID],tblAccounts[Include],FALSE),FALSE),SUMIFS(tblAcctSummary[Income_Other_Base],tblAcctSummary[Account_ID],A11),0)) | J11: =IF(A11="","",SUM(G11:I11)) | K11: =IF(A11="","",IF(IFERROR(XLOOKUP(A11,tblAccounts[Account_ID],tblAccounts[Include],FALSE),FALSE),SUMIFS(tblAcctSummary[Realized_GL_Base],tblAcctSummary[Account_ID],A11),0)) | L11: =IF(A11="","",IF(IFERROR(XLOOKUP(A11,tblAccounts[Account_ID],tblAccounts[Include],FALSE),FALSE),SUMIFS(tblAcctSummary[Fees_Base],tblAcctSummary[Account_ID],A11),0)) | M11: =IF(A11="","",IF(IFERROR(XLOOKUP(A11,tblAccounts[Account_ID],tblAccounts[Include],FALSE),FALSE),SUMIFS(tblAcctSummary[Taxes_Base],tblAcctSummary[Account_ID],A11),0)) | N11: =IF(A11="","",IF(IFERROR(XLOOKUP(A11,tblAccounts[Account_ID],tblAccounts[Include],FALSE),FALSE),IFERROR(SUMPRODUCT(tblAcctSummary[Return_Period],tblAcctSummary[Begin_Balance_Base],--(tblAcctSummary[Account_ID]=A11))/IF(SUMIFS(tblAcctSummary[Begin_Balance_Base],tblAcctSummary[Account_ID],A11)=0,NA(),SUMIFS(tblAcctSummary[Begin_Balance_Base],tblAcctSummary[Account_ID],A11)),0),0))
A12: =IFERROR(INDEX(tblAccounts[Account_ID],9),"") | B12: =IF(A12="","",IFERROR(XLOOKUP(A12,tblAccounts[Account_ID],tblAccounts[Account_Name],""),"")) | C12: =IF(A12="","",IFERROR(XLOOKUP(A12,tblAccounts[Account_ID],tblAccounts[Household_ID],""),"")) | D12: =IF(A12="","",IF(IFERROR(XLOOKUP(A12,tblAccounts[Account_ID],tblAccounts[Include],FALSE),FALSE),SUMIFS(tblAcctSummary[Begin_Balance_Base],tblAcctSummary[Account_ID],A12),0)) | E12: =IF(A12="","",IF(IFERROR(XLOOKUP(A12,tblAccounts[Account_ID],tblAccounts[Include],FALSE),FALSE),SUMIFS(tblAcctSummary[End_Balance_Base],tblAcctSummary[Account_ID],A12),0)) | F12: =IF(A12="","",IF(IFERROR(XLOOKUP(A12,tblAccounts[Account_ID],tblAccounts[Include],FALSE),FALSE),SUMIFS(tblAcctSummary[Net_Contrib_Base],tblAcctSummary[Account_ID],A12),0)) | G12: =IF(A12="","",IF(IFERROR(XLOOKUP(A12,tblAccounts[Account_ID],tblAccounts[Include],FALSE),FALSE),SUMIFS(tblAcctSummary[Income_Interest_Base],tblAcctSummary[Account_ID],A12),0)) | H12: =IF(A12="","",IF(IFERROR(XLOOKUP(A12,tblAccounts[Account_ID],tblAccounts[Include],FALSE),FALSE),SUMIFS(tblAcctSummary[Income_Dividends_Base],tblAcctSummary[Account_ID],A12),0)) | I12: =IF(A12="","",IF(IFERROR(XLOOKUP(A12,tblAccounts[Account_ID],tblAccounts[Include],FALSE),FALSE),SUMIFS(tblAcctSummary[Income_Other_Base],tblAcctSummary[Account_ID],A12),0)) | J12: =IF(A12="","",SUM(G12:I12)) | K12: =IF(A12="","",IF(IFERROR(XLOOKUP(A12,tblAccounts[Account_ID],tblAccounts[Include],FALSE),FALSE),SUMIFS(tblAcctSummary[Realized_GL_Base],tblAcctSummary[Account_ID],A12),0)) | L12: =IF(A12="","",IF(IFERROR(XLOOKUP(A12,tblAccounts[Account_ID],tblAccounts[Include],FALSE),FALSE),SUMIFS(tblAcctSummary[Fees_Base],tblAcctSummary[Account_ID],A12),0)) | M12: =IF(A12="","",IF(IFERROR(XLOOKUP(A12,tblAccounts[Account_ID],tblAccounts[Include],FALSE),FALSE),SUMIFS(tblAcctSummary[Taxes_Base],tblAcctSummary[Account_ID],A12),0)) | N12: =IF(A12="","",IF(IFERROR(XLOOKUP(A12,tblAccounts[Account_ID],tblAccounts[Include],FALSE),FALSE),IFERROR(SUMPRODUCT(tblAcctSummary[Return_Period],tblAcctSummary[Begin_Balance_Base],--(tblAcctSummary[Account_ID]=A12))/IF(SUMIFS(tblAcctSummary[Begin_Balance_Base],tblAcctSummary[Account_ID],A12)=0,NA(),SUMIFS(tblAcctSummary[Begin_Balance_Base],tblAcctSummary[Account_ID],A12)),0),0))
A13: =IFERROR(INDEX(tblAccounts[Account_ID],10),"") | B13: =IF(A13="","",IFERROR(XLOOKUP(A13,tblAccounts[Account_ID],tblAccounts[Account_Name],""),"")) | C13: =IF(A13="","",IFERROR(XLOOKUP(A13,tblAccounts[Account_ID],tblAccounts[Household_ID],""),"")) | D13: =IF(A13="","",IF(IFERROR(XLOOKUP(A13,tblAccounts[Account_ID],tblAccounts[Include],FALSE),FALSE),SUMIFS(tblAcctSummary[Begin_Balance_Base],tblAcctSummary[Account_ID],A13),0)) | E13: =IF(A13="","",IF(IFERROR(XLOOKUP(A13,tblAccounts[Account_ID],tblAccounts[Include],FALSE),FALSE),SUMIFS(tblAcctSummary[End_Balance_Base],tblAcctSummary[Account_ID],A13),0)) | F13: =IF(A13="","",IF(IFERROR(XLOOKUP(A13,tblAccounts[Account_ID],tblAccounts[Include],FALSE),FALSE),SUMIFS(tblAcctSummary[Net_Contrib_Base],tblAcctSummary[Account_ID],A13),0)) | G13: =IF(A13="","",IF(IFERROR(XLOOKUP(A13,tblAccounts[Account_ID],tblAccounts[Include],FALSE),FALSE),SUMIFS(tblAcctSummary[Income_Interest_Base],tblAcctSummary[Account_ID],A13),0)) | H13: =IF(A13="","",IF(IFERROR(XLOOKUP(A13,tblAccounts[Account_ID],tblAccounts[Include],FALSE),FALSE),SUMIFS(tblAcctSummary[Income_Dividends_Base],tblAcctSummary[Account_ID],A13),0)) | I13: =IF(A13="","",IF(IFERROR(XLOOKUP(A13,tblAccounts[Account_ID],tblAccounts[Include],FALSE),FALSE),SUMIFS(tblAcctSummary[Income_Other_Base],tblAcctSummary[Account_ID],A13),0)) | J13: =IF(A13="","",SUM(G13:I13)) | K13: =IF(A13="","",IF(IFERROR(XLOOKUP(A13,tblAccounts[Account_ID],tblAccounts[Include],FALSE),FALSE),SUMIFS(tblAcctSummary[Realized_GL_Base],tblAcctSummary[Account_ID],A13),0)) | L13: =IF(A13="","",IF(IFERROR(XLOOKUP(A13,tblAccounts[Account_ID],tblAccounts[Include],FALSE),FALSE),SUMIFS(tblAcctSummary[Fees_Base],tblAcctSummary[Account_ID],A13),0)) | M13: =IF(A13="","",IF(IFERROR(XLOOKUP(A13,tblAccounts[Account_ID],tblAccounts[Include],FALSE),FALSE),SUMIFS(tblAcctSummary[Taxes_Base],tblAcctSummary[Account_ID],A13),0)) | N13: =IF(A13="","",IF(IFERROR(XLOOKUP(A13,tblAccounts[Account_ID],tblAccounts[Include],FALSE),FALSE),IFERROR(SUMPRODUCT(tblAcctSummary[Return_Period],tblAcctSummary[Begin_Balance_Base],--(tblAcctSummary[Account_ID]=A13))/IF(SUMIFS(tblAcctSummary[Begin_Balance_Base],tblAcctSummary[Account_ID],A13)=0,NA(),SUMIFS(tblAcctSummary[Begin_Balance_Base],tblAcctSummary[Account_ID],A13)),0),0))
A14: =IFERROR(INDEX(tblAccounts[Account_ID],11),"") | B14: =IF(A14="","",IFERROR(XLOOKUP(A14,tblAccounts[Account_ID],tblAccounts[Account_Name],""),"")) | C14: =IF(A14="","",IFERROR(XLOOKUP(A14,tblAccounts[Account_ID],tblAccounts[Household_ID],""),"")) | D14: =IF(A14="","",IF(IFERROR(XLOOKUP(A14,tblAccounts[Account_ID],tblAccounts[Include],FALSE),FALSE),SUMIFS(tblAcctSummary[Begin_Balance_Base],tblAcctSummary[Account_ID],A14),0)) | E14: =IF(A14="","",IF(IFERROR(XLOOKUP(A14,tblAccounts[Account_ID],tblAccounts[Include],FALSE),FALSE),SUMIFS(tblAcctSummary[End_Balance_Base],tblAcctSummary[Account_ID],A14),0)) | F14: =IF(A14="","",IF(IFERROR(XLOOKUP(A14,tblAccounts[Account_ID],tblAccounts[Include],FALSE),FALSE),SUMIFS(tblAcctSummary[Net_Contrib_Base],tblAcctSummary[Account_ID],A14),0)) | G14: =IF(A14="","",IF(IFERROR(XLOOKUP(A14,tblAccounts[Account_ID],tblAccounts[Include],FALSE),FALSE),SUMIFS(tblAcctSummary[Income_Interest_Base],tblAcctSummary[Account_ID],A14),0)) | H14: =IF(A14="","",IF(IFERROR(XLOOKUP(A14,tblAccounts[Account_ID],tblAccounts[Include],FALSE),FALSE),SUMIFS(tblAcctSummary[Income_Dividends_Base],tblAcctSummary[Account_ID],A14),0)) | I14: =IF(A14="","",IF(IFERROR(XLOOKUP(A14,tblAccounts[Account_ID],tblAccounts[Include],FALSE),FALSE),SUMIFS(tblAcctSummary[Income_Other_Base],tblAcctSummary[Account_ID],A14),0)) | J14: =IF(A14="","",SUM(G14:I14)) | K14: =IF(A14="","",IF(IFERROR(XLOOKUP(A14,tblAccounts[Account_ID],tblAccounts[Include],FALSE),FALSE),SUMIFS(tblAcctSummary[Realized_GL_Base],tblAcctSummary[Account_ID],A14),0)) | L14: =IF(A14="","",IF(IFERROR(XLOOKUP(A14,tblAccounts[Account_ID],tblAccounts[Include],FALSE),FALSE),SUMIFS(tblAcctSummary[Fees_Base],tblAcctSummary[Account_ID],A14),0)) | M14: =IF(A14="","",IF(IFERROR(XLOOKUP(A14,tblAccounts[Account_ID],tblAccounts[Include],FALSE),FALSE),SUMIFS(tblAcctSummary[Taxes_Base],tblAcctSummary[Account_ID],A14),0)) | N14: =IF(A14="","",IF(IFERROR(XLOOKUP(A14,tblAccounts[Account_ID],tblAccounts[Include],FALSE),FALSE),IFERROR(SUMPRODUCT(tblAcctSummary[Return_Period],tblAcctSummary[Begin_Balance_Base],--(tblAcctSummary[Account_ID]=A14))/IF(SUMIFS(tblAcctSummary[Begin_Balance_Base],tblAcctSummary[Account_ID],A14)=0,NA(),SUMIFS(tblAcctSummary[Begin_Balance_Base],tblAcctSummary[Account_ID],A14)),0),0))
A15: =IFERROR(INDEX(tblAccounts[Account_ID],12),"") | B15: =IF(A15="","",IFERROR(XLOOKUP(A15,tblAccounts[Account_ID],tblAccounts[Account_Name],""),"")) | C15: =IF(A15="","",IFERROR(XLOOKUP(A15,tblAccounts[Account_ID],tblAccounts[Household_ID],""),"")) | D15: =IF(A15="","",IF(IFERROR(XLOOKUP(A15,tblAccounts[Account_ID],tblAccounts[Include],FALSE),FALSE),SUMIFS(tblAcctSummary[Begin_Balance_Base],tblAcctSummary[Account_ID],A15),0)) | E15: =IF(A15="","",IF(IFERROR(XLOOKUP(A15,tblAccounts[Account_ID],tblAccounts[Include],FALSE),FALSE),SUMIFS(tblAcctSummary[End_Balance_Base],tblAcctSummary[Account_ID],A15),0)) | F15: =IF(A15="","",IF(IFERROR(XLOOKUP(A15,tblAccounts[Account_ID],tblAccounts[Include],FALSE),FALSE),SUMIFS(tblAcctSummary[Net_Contrib_Base],tblAcctSummary[Account_ID],A15),0)) | G15: =IF(A15="","",IF(IFERROR(XLOOKUP(A15,tblAccounts[Account_ID],tblAccounts[Include],FALSE),FALSE),SUMIFS(tblAcctSummary[Income_Interest_Base],tblAcctSummary[Account_ID],A15),0)) | H15: =IF(A15="","",IF(IFERROR(XLOOKUP(A15,tblAccounts[Account_ID],tblAccounts[Include],FALSE),FALSE),SUMIFS(tblAcctSummary[Income_Dividends_Base],tblAcctSummary[Account_ID],A15),0)) | I15: =IF(A15="","",IF(IFERROR(XLOOKUP(A15,tblAccounts[Account_ID],tblAccounts[Include],FALSE),FALSE),SUMIFS(tblAcctSummary[Income_Other_Base],tblAcctSummary[Account_ID],A15),0)) | J15: =IF(A15="","",SUM(G15:I15)) | K15: =IF(A15="","",IF(IFERROR(XLOOKUP(A15,tblAccounts[Account_ID],tblAccounts[Include],FALSE),FALSE),SUMIFS(tblAcctSummary[Realized_GL_Base],tblAcctSummary[Account_ID],A15),0)) | L15: =IF(A15="","",IF(IFERROR(XLOOKUP(A15,tblAccounts[Account_ID],tblAccounts[Include],FALSE),FALSE),SUMIFS(tblAcctSummary[Fees_Base],tblAcctSummary[Account_ID],A15),0)) | M15: =IF(A15="","",IF(IFERROR(XLOOKUP(A15,tblAccounts[Account_ID],tblAccounts[Include],FALSE),FALSE),SUMIFS(tblAcctSummary[Taxes_Base],tblAcctSummary[Account_ID],A15),0)) | N15: =IF(A15="","",IF(IFERROR(XLOOKUP(A15,tblAccounts[Account_ID],tblAccounts[Include],FALSE),FALSE),IFERROR(SUMPRODUCT(tblAcctSummary[Return_Period],tblAcctSummary[Begin_Balance_Base],--(tblAcctSummary[Account_ID]=A15))/IF(SUMIFS(tblAcctSummary[Begin_Balance_Base],tblAcctSummary[Account_ID],A15)=0,NA(),SUMIFS(tblAcctSummary[Begin_Balance_Base],tblAcctSummary[Account_ID],A15)),0),0))
A16: =IFERROR(INDEX(tblAccounts[Account_ID],13),"") | B16: =IF(A16="","",IFERROR(XLOOKUP(A16,tblAccounts[Account_ID],tblAccounts[Account_Name],""),"")) | C16: =IF(A16="","",IFERROR(XLOOKUP(A16,tblAccounts[Account_ID],tblAccounts[Household_ID],""),"")) | D16: =IF(A16="","",IF(IFERROR(XLOOKUP(A16,tblAccounts[Account_ID],tblAccounts[Include],FALSE),FALSE),SUMIFS(tblAcctSummary[Begin_Balance_Base],tblAcctSummary[Account_ID],A16),0)) | E16: =IF(A16="","",IF(IFERROR(XLOOKUP(A16,tblAccounts[Account_ID],tblAccounts[Include],FALSE),FALSE),SUMIFS(tblAcctSummary[End_Balance_Base],tblAcctSummary[Account_ID],A16),0)) | F16: =IF(A16="","",IF(IFERROR(XLOOKUP(A16,tblAccounts[Account_ID],tblAccounts[Include],FALSE),FALSE),SUMIFS(tblAcctSummary[Net_Contrib_Base],tblAcctSummary[Account_ID],A16),0)) | G16: =IF(A16="","",IF(IFERROR(XLOOKUP(A16,tblAccounts[Account_ID],tblAccounts[Include],FALSE),FALSE),SUMIFS(tblAcctSummary[Income_Interest_Base],tblAcctSummary[Account_ID],A16),0)) | H16: =IF(A16="","",IF(IFERROR(XLOOKUP(A16,tblAccounts[Account_ID],tblAccounts[Include],FALSE),FALSE),SUMIFS(tblAcctSummary[Income_Dividends_Base],tblAcctSummary[Account_ID],A16),0)) | I16: =IF(A16="","",IF(IFERROR(XLOOKUP(A16,tblAccounts[Account_ID],tblAccounts[Include],FALSE),FALSE),SUMIFS(tblAcctSummary[Income_Other_Base],tblAcctSummary[Account_ID],A16),0)) | J16: =IF(A16="","",SUM(G16:I16)) | K16: =IF(A16="","",IF(IFERROR(XLOOKUP(A16,tblAccounts[Account_ID],tblAccounts[Include],FALSE),FALSE),SUMIFS(tblAcctSummary[Realized_GL_Base],tblAcctSummary[Account_ID],A16),0)) | L16: =IF(A16="","",IF(IFERROR(XLOOKUP(A16,tblAccounts[Account_ID],tblAccounts[Include],FALSE),FALSE),SUMIFS(tblAcctSummary[Fees_Base],tblAcctSummary[Account_ID],A16),0)) | M16: =IF(A16="","",IF(IFERROR(XLOOKUP(A16,tblAccounts[Account_ID],tblAccounts[Include],FALSE),FALSE),SUMIFS(tblAcctSummary[Taxes_Base],tblAcctSummary[Account_ID],A16),0)) | N16: =IF(A16="","",IF(IFERROR(XLOOKUP(A16,tblAccounts[Account_ID],tblAccounts[Include],FALSE),FALSE),IFERROR(SUMPRODUCT(tblAcctSummary[Return_Period],tblAcctSummary[Begin_Balance_Base],--(tblAcctSummary[Account_ID]=A16))/IF(SUMIFS(tblAcctSummary[Begin_Balance_Base],tblAcctSummary[Account_ID],A16)=0,NA(),SUMIFS(tblAcctSummary[Begin_Balance_Base],tblAcctSummary[Account_ID],A16)),0),0))
A17: =IFERROR(INDEX(tblAccounts[Account_ID],14),"") | B17: =IF(A17="","",IFERROR(XLOOKUP(A17,tblAccounts[Account_ID],tblAccounts[Account_Name],""),"")) | C17: =IF(A17="","",IFERROR(XLOOKUP(A17,tblAccounts[Account_ID],tblAccounts[Household_ID],""),"")) | D17: =IF(A17="","",IF(IFERROR(XLOOKUP(A17,tblAccounts[Account_ID],tblAccounts[Include],FALSE),FALSE),SUMIFS(tblAcctSummary[Begin_Balance_Base],tblAcctSummary[Account_ID],A17),0)) | E17: =IF(A17="","",IF(IFERROR(XLOOKUP(A17,tblAccounts[Account_ID],tblAccounts[Include],FALSE),FALSE),SUMIFS(tblAcctSummary[End_Balance_Base],tblAcctSummary[Account_ID],A17),0)) | F17: =IF(A17="","",IF(IFERROR(XLOOKUP(A17,tblAccounts[Account_ID],tblAccounts[Include],FALSE),FALSE),SUMIFS(tblAcctSummary[Net_Contrib_Base],tblAcctSummary[Account_ID],A17),0)) | G17: =IF(A17="","",IF(IFERROR(XLOOKUP(A17,tblAccounts[Account_ID],tblAccounts[Include],FALSE),FALSE),SUMIFS(tblAcctSummary[Income_Interest_Base],tblAcctSummary[Account_ID],A17),0)) | H17: =IF(A17="","",IF(IFERROR(XLOOKUP(A17,tblAccounts[Account_ID],tblAccounts[Include],FALSE),FALSE),SUMIFS(tblAcctSummary[Income_Dividends_Base],tblAcctSummary[Account_ID],A17),0)) | I17: =IF(A17="","",IF(IFERROR(XLOOKUP(A17,tblAccounts[Account_ID],tblAccounts[Include],FALSE),FALSE),SUMIFS(tblAcctSummary[Income_Other_Base],tblAcctSummary[Account_ID],A17),0)) | J17: =IF(A17="","",SUM(G17:I17)) | K17: =IF(A17="","",IF(IFERROR(XLOOKUP(A17,tblAccounts[Account_ID],tblAccounts[Include],FALSE),FALSE),SUMIFS(tblAcctSummary[Realized_GL_Base],tblAcctSummary[Account_ID],A17),0)) | L17: =IF(A17="","",IF(IFERROR(XLOOKUP(A17,tblAccounts[Account_ID],tblAccounts[Include],FALSE),FALSE),SUMIFS(tblAcctSummary[Fees_Base],tblAcctSummary[Account_ID],A17),0)) | M17: =IF(A17="","",IF(IFERROR(XLOOKUP(A17,tblAccounts[Account_ID],tblAccounts[Include],FALSE),FALSE),SUMIFS(tblAcctSummary[Taxes_Base],tblAcctSummary[Account_ID],A17),0)) | N17: =IF(A17="","",IF(IFERROR(XLOOKUP(A17,tblAccounts[Account_ID],tblAccounts[Include],FALSE),FALSE),IFERROR(SUMPRODUCT(tblAcctSummary[Return_Period],tblAcctSummary[Begin_Balance_Base],--(tblAcctSummary[Account_ID]=A17))/IF(SUMIFS(tblAcctSummary[Begin_Balance_Base],tblAcctSummary[Account_ID],A17)=0,NA(),SUMIFS(tblAcctSummary[Begin_Balance_Base],tblAcctSummary[Account_ID],A17)),0),0))
A18: =IFERROR(INDEX(tblAccounts[Account_ID],15),"") | B18: =IF(A18="","",IFERROR(XLOOKUP(A18,tblAccounts[Account_ID],tblAccounts[Account_Name],""),"")) | C18: =IF(A18="","",IFERROR(XLOOKUP(A18,tblAccounts[Account_ID],tblAccounts[Household_ID],""),"")) | D18: =IF(A18="","",IF(IFERROR(XLOOKUP(A18,tblAccounts[Account_ID],tblAccounts[Include],FALSE),FALSE),SUMIFS(tblAcctSummary[Begin_Balance_Base],tblAcctSummary[Account_ID],A18),0)) | E18: =IF(A18="","",IF(IFERROR(XLOOKUP(A18,tblAccounts[Account_ID],tblAccounts[Include],FALSE),FALSE),SUMIFS(tblAcctSummary[End_Balance_Base],tblAcctSummary[Account_ID],A18),0)) | F18: =IF(A18="","",IF(IFERROR(XLOOKUP(A18,tblAccounts[Account_ID],tblAccounts[Include],FALSE),FALSE),SUMIFS(tblAcctSummary[Net_Contrib_Base],tblAcctSummary[Account_ID],A18),0)) | G18: =IF(A18="","",IF(IFERROR(XLOOKUP(A18,tblAccounts[Account_ID],tblAccounts[Include],FALSE),FALSE),SUMIFS(tblAcctSummary[Income_Interest_Base],tblAcctSummary[Account_ID],A18),0)) | H18: =IF(A18="","",IF(IFERROR(XLOOKUP(A18,tblAccounts[Account_ID],tblAccounts[Include],FALSE),FALSE),SUMIFS(tblAcctSummary[Income_Dividends_Base],tblAcctSummary[Account_ID],A18),0)) | I18: =IF(A18="","",IF(IFERROR(XLOOKUP(A18,tblAccounts[Account_ID],tblAccounts[Include],FALSE),FALSE),SUMIFS(tblAcctSummary[Income_Other_Base],tblAcctSummary[Account_ID],A18),0)) | J18: =IF(A18="","",SUM(G18:I18)) | K18: =IF(A18="","",IF(IFERROR(XLOOKUP(A18,tblAccounts[Account_ID],tblAccounts[Include],FALSE),FALSE),SUMIFS(tblAcctSummary[Realized_GL_Base],tblAcctSummary[Account_ID],A18),0)) | L18: =IF(A18="","",IF(IFERROR(XLOOKUP(A18,tblAccounts[Account_ID],tblAccounts[Include],FALSE),FALSE),SUMIFS(tblAcctSummary[Fees_Base],tblAcctSummary[Account_ID],A18),0)) | M18: =IF(A18="","",IF(IFERROR(XLOOKUP(A18,tblAccounts[Account_ID],tblAccounts[Include],FALSE),FALSE),SUMIFS(tblAcctSummary[Taxes_Base],tblAcctSummary[Account_ID],A18),0)) | N18: =IF(A18="","",IF(IFERROR(XLOOKUP(A18,tblAccounts[Account_ID],tblAccounts[Include],FALSE),FALSE),IFERROR(SUMPRODUCT(tblAcctSummary[Return_Period],tblAcctSummary[Begin_Balance_Base],--(tblAcctSummary[Account_ID]=A18))/IF(SUMIFS(tblAcctSummary[Begin_Balance_Base],tblAcctSummary[Account_ID],A18)=0,NA(),SUMIFS(tblAcctSummary[Begin_Balance_Base],tblAcctSummary[Account_ID],A18)),0),0))
A19: =IFERROR(INDEX(tblAccounts[Account_ID],16),"") | B19: =IF(A19="","",IFERROR(XLOOKUP(A19,tblAccounts[Account_ID],tblAccounts[Account_Name],""),"")) | C19: =IF(A19="","",IFERROR(XLOOKUP(A19,tblAccounts[Account_ID],tblAccounts[Household_ID],""),"")) | D19: =IF(A19="","",IF(IFERROR(XLOOKUP(A19,tblAccounts[Account_ID],tblAccounts[Include],FALSE),FALSE),SUMIFS(tblAcctSummary[Begin_Balance_Base],tblAcctSummary[Account_ID],A19),0)) | E19: =IF(A19="","",IF(IFERROR(XLOOKUP(A19,tblAccounts[Account_ID],tblAccounts[Include],FALSE),FALSE),SUMIFS(tblAcctSummary[End_Balance_Base],tblAcctSummary[Account_ID],A19),0)) | F19: =IF(A19="","",IF(IFERROR(XLOOKUP(A19,tblAccounts[Account_ID],tblAccounts[Include],FALSE),FALSE),SUMIFS(tblAcctSummary[Net_Contrib_Base],tblAcctSummary[Account_ID],A19),0)) | G19: =IF(A19="","",IF(IFERROR(XLOOKUP(A19,tblAccounts[Account_ID],tblAccounts[Include],FALSE),FALSE),SUMIFS(tblAcctSummary[Income_Interest_Base],tblAcctSummary[Account_ID],A19),0)) | H19: =IF(A19="","",IF(IFERROR(XLOOKUP(A19,tblAccounts[Account_ID],tblAccounts[Include],FALSE),FALSE),SUMIFS(tblAcctSummary[Income_Dividends_Base],tblAcctSummary[Account_ID],A19),0)) | I19: =IF(A19="","",IF(IFERROR(XLOOKUP(A19,tblAccounts[Account_ID],tblAccounts[Include],FALSE),FALSE),SUMIFS(tblAcctSummary[Income_Other_Base],tblAcctSummary[Account_ID],A19),0)) | J19: =IF(A19="","",SUM(G19:I19)) | K19: =IF(A19="","",IF(IFERROR(XLOOKUP(A19,tblAccounts[Account_ID],tblAccounts[Include],FALSE),FALSE),SUMIFS(tblAcctSummary[Realized_GL_Base],tblAcctSummary[Account_ID],A19),0)) | L19: =IF(A19="","",IF(IFERROR(XLOOKUP(A19,tblAccounts[Account_ID],tblAccounts[Include],FALSE),FALSE),SUMIFS(tblAcctSummary[Fees_Base],tblAcctSummary[Account_ID],A19),0)) | M19: =IF(A19="","",IF(IFERROR(XLOOKUP(A19,tblAccounts[Account_ID],tblAccounts[Include],FALSE),FALSE),SUMIFS(tblAcctSummary[Taxes_Base],tblAcctSummary[Account_ID],A19),0)) | N19: =IF(A19="","",IF(IFERROR(XLOOKUP(A19,tblAccounts[Account_ID],tblAccounts[Include],FALSE),FALSE),IFERROR(SUMPRODUCT(tblAcctSummary[Return_Period],tblAcctSummary[Begin_Balance_Base],--(tblAcctSummary[Account_ID]=A19))/IF(SUMIFS(tblAcctSummary[Begin_Balance_Base],tblAcctSummary[Account_ID],A19)=0,NA(),SUMIFS(tblAcctSummary[Begin_Balance_Base],tblAcctSummary[Account_ID],A19)),0),0))
A20: =IFERROR(INDEX(tblAccounts[Account_ID],17),"") | B20: =IF(A20="","",IFERROR(XLOOKUP(A20,tblAccounts[Account_ID],tblAccounts[Account_Name],""),"")) | C20: =IF(A20="","",IFERROR(XLOOKUP(A20,tblAccounts[Account_ID],tblAccounts[Household_ID],""),"")) | D20: =IF(A20="","",IF(IFERROR(XLOOKUP(A20,tblAccounts[Account_ID],tblAccounts[Include],FALSE),FALSE),SUMIFS(tblAcctSummary[Begin_Balance_Base],tblAcctSummary[Account_ID],A20),0)) | E20: =IF(A20="","",IF(IFERROR(XLOOKUP(A20,tblAccounts[Account_ID],tblAccounts[Include],FALSE),FALSE),SUMIFS(tblAcctSummary[End_Balance_Base],tblAcctSummary[Account_ID],A20),0)) | F20: =IF(A20="","",IF(IFERROR(XLOOKUP(A20,tblAccounts[Account_ID],tblAccounts[Include],FALSE),FALSE),SUMIFS(tblAcctSummary[Net_Contrib_Base],tblAcctSummary[Account_ID],A20),0)) | G20: =IF(A20="","",IF(IFERROR(XLOOKUP(A20,tblAccounts[Account_ID],tblAccounts[Include],FALSE),FALSE),SUMIFS(tblAcctSummary[Income_Interest_Base],tblAcctSummary[Account_ID],A20),0)) | H20: =IF(A20="","",IF(IFERROR(XLOOKUP(A20,tblAccounts[Account_ID],tblAccounts[Include],FALSE),FALSE),SUMIFS(tblAcctSummary[Income_Dividends_Base],tblAcctSummary[Account_ID],A20),0)) | I20: =IF(A20="","",IF(IFERROR(XLOOKUP(A20,tblAccounts[Account_ID],tblAccounts[Include],FALSE),FALSE),SUMIFS(tblAcctSummary[Income_Other_Base],tblAcctSummary[Account_ID],A20),0)) | J20: =IF(A20="","",SUM(G20:I20)) | K20: =IF(A20="","",IF(IFERROR(XLOOKUP(A20,tblAccounts[Account_ID],tblAccounts[Include],FALSE),FALSE),SUMIFS(tblAcctSummary[Realized_GL_Base],tblAcctSummary[Account_ID],A20),0)) | L20: =IF(A20="","",IF(IFERROR(XLOOKUP(A20,tblAccounts[Account_ID],tblAccounts[Include],FALSE),FALSE),SUMIFS(tblAcctSummary[Fees_Base],tblAcctSummary[Account_ID],A20),0)) | M20: =IF(A20="","",IF(IFERROR(XLOOKUP(A20,tblAccounts[Account_ID],tblAccounts[Include],FALSE),FALSE),SUMIFS(tblAcctSummary[Taxes_Base],tblAcctSummary[Account_ID],A20),0)) | N20: =IF(A20="","",IF(IFERROR(XLOOKUP(A20,tblAccounts[Account_ID],tblAccounts[Include],FALSE),FALSE),IFERROR(SUMPRODUCT(tblAcctSummary[Return_Period],tblAcctSummary[Begin_Balance_Base],--(tblAcctSummary[Account_ID]=A20))/IF(SUMIFS(tblAcctSummary[Begin_Balance_Base],tblAcctSummary[Account_ID],A20)=0,NA(),SUMIFS(tblAcctSummary[Begin_Balance_Base],tblAcctSummary[Account_ID],A20)),0),0))
A21: =IFERROR(INDEX(tblAccounts[Account_ID],18),"") | B21: =IF(A21="","",IFERROR(XLOOKUP(A21,tblAccounts[Account_ID],tblAccounts[Account_Name],""),"")) | C21: =IF(A21="","",IFERROR(XLOOKUP(A21,tblAccounts[Account_ID],tblAccounts[Household_ID],""),"")) | D21: =IF(A21="","",IF(IFERROR(XLOOKUP(A21,tblAccounts[Account_ID],tblAccounts[Include],FALSE),FALSE),SUMIFS(tblAcctSummary[Begin_Balance_Base],tblAcctSummary[Account_ID],A21),0)) | E21: =IF(A21="","",IF(IFERROR(XLOOKUP(A21,tblAccounts[Account_ID],tblAccounts[Include],FALSE),FALSE),SUMIFS(tblAcctSummary[End_Balance_Base],tblAcctSummary[Account_ID],A21),0)) | F21: =IF(A21="","",IF(IFERROR(XLOOKUP(A21,tblAccounts[Account_ID],tblAccounts[Include],FALSE),FALSE),SUMIFS(tblAcctSummary[Net_Contrib_Base],tblAcctSummary[Account_ID],A21),0)) | G21: =IF(A21="","",IF(IFERROR(XLOOKUP(A21,tblAccounts[Account_ID],tblAccounts[Include],FALSE),FALSE),SUMIFS(tblAcctSummary[Income_Interest_Base],tblAcctSummary[Account_ID],A21),0)) | H21: =IF(A21="","",IF(IFERROR(XLOOKUP(A21,tblAccounts[Account_ID],tblAccounts[Include],FALSE),FALSE),SUMIFS(tblAcctSummary[Income_Dividends_Base],tblAcctSummary[Account_ID],A21),0)) | I21: =IF(A21="","",IF(IFERROR(XLOOKUP(A21,tblAccounts[Account_ID],tblAccounts[Include],FALSE),FALSE),SUMIFS(tblAcctSummary[Income_Other_Base],tblAcctSummary[Account_ID],A21),0)) | J21: =IF(A21="","",SUM(G21:I21)) | K21: =IF(A21="","",IF(IFERROR(XLOOKUP(A21,tblAccounts[Account_ID],tblAccounts[Include],FALSE),FALSE),SUMIFS(tblAcctSummary[Realized_GL_Base],tblAcctSummary[Account_ID],A21),0)) | L21: =IF(A21="","",IF(IFERROR(XLOOKUP(A21,tblAccounts[Account_ID],tblAccounts[Include],FALSE),FALSE),SUMIFS(tblAcctSummary[Fees_Base],tblAcctSummary[Account_ID],A21),0)) | M21: =IF(A21="","",IF(IFERROR(XLOOKUP(A21,tblAccounts[Account_ID],tblAccounts[Include],FALSE),FALSE),SUMIFS(tblAcctSummary[Taxes_Base],tblAcctSummary[Account_ID],A21),0)) | N21: =IF(A21="","",IF(IFERROR(XLOOKUP(A21,tblAccounts[Account_ID],tblAccounts[Include],FALSE),FALSE),IFERROR(SUMPRODUCT(tblAcctSummary[Return_Period],tblAcctSummary[Begin_Balance_Base],--(tblAcctSummary[Account_ID]=A21))/IF(SUMIFS(tblAcctSummary[Begin_Balance_Base],tblAcctSummary[Account_ID],A21)=0,NA(),SUMIFS(tblAcctSummary[Begin_Balance_Base],tblAcctSummary[Account_ID],A21)),0),0))
A22: =IFERROR(INDEX(tblAccounts[Account_ID],19),"") | B22: =IF(A22="","",IFERROR(XLOOKUP(A22,tblAccounts[Account_ID],tblAccounts[Account_Name],""),"")) | C22: =IF(A22="","",IFERROR(XLOOKUP(A22,tblAccounts[Account_ID],tblAccounts[Household_ID],""),"")) | D22: =IF(A22="","",IF(IFERROR(XLOOKUP(A22,tblAccounts[Account_ID],tblAccounts[Include],FALSE),FALSE),SUMIFS(tblAcctSummary[Begin_Balance_Base],tblAcctSummary[Account_ID],A22),0)) | E22: =IF(A22="","",IF(IFERROR(XLOOKUP(A22,tblAccounts[Account_ID],tblAccounts[Include],FALSE),FALSE),SUMIFS(tblAcctSummary[End_Balance_Base],tblAcctSummary[Account_ID],A22),0)) | F22: =IF(A22="","",IF(IFERROR(XLOOKUP(A22,tblAccounts[Account_ID],tblAccounts[Include],FALSE),FALSE),SUMIFS(tblAcctSummary[Net_Contrib_Base],tblAcctSummary[Account_ID],A22),0)) | G22: =IF(A22="","",IF(IFERROR(XLOOKUP(A22,tblAccounts[Account_ID],tblAccounts[Include],FALSE),FALSE),SUMIFS(tblAcctSummary[Income_Interest_Base],tblAcctSummary[Account_ID],A22),0)) | H22: =IF(A22="","",IF(IFERROR(XLOOKUP(A22,tblAccounts[Account_ID],tblAccounts[Include],FALSE),FALSE),SUMIFS(tblAcctSummary[Income_Dividends_Base],tblAcctSummary[Account_ID],A22),0)) | I22: =IF(A22="","",IF(IFERROR(XLOOKUP(A22,tblAccounts[Account_ID],tblAccounts[Include],FALSE),FALSE),SUMIFS(tblAcctSummary[Income_Other_Base],tblAcctSummary[Account_ID],A22),0)) | J22: =IF(A22="","",SUM(G22:I22)) | K22: =IF(A22="","",IF(IFERROR(XLOOKUP(A22,tblAccounts[Account_ID],tblAccounts[Include],FALSE),FALSE),SUMIFS(tblAcctSummary[Realized_GL_Base],tblAcctSummary[Account_ID],A22),0)) | L22: =IF(A22="","",IF(IFERROR(XLOOKUP(A22,tblAccounts[Account_ID],tblAccounts[Include],FALSE),FALSE),SUMIFS(tblAcctSummary[Fees_Base],tblAcctSummary[Account_ID],A22),0)) | M22: =IF(A22="","",IF(IFERROR(XLOOKUP(A22,tblAccounts[Account_ID],tblAccounts[Include],FALSE),FALSE),SUMIFS(tblAcctSummary[Taxes_Base],tblAcctSummary[Account_ID],A22),0)) | N22: =IF(A22="","",IF(IFERROR(XLOOKUP(A22,tblAccounts[Account_ID],tblAccounts[Include],FALSE),FALSE),IFERROR(SUMPRODUCT(tblAcctSummary[Return_Period],tblAcctSummary[Begin_Balance_Base],--(tblAcctSummary[Account_ID]=A22))/IF(SUMIFS(tblAcctSummary[Begin_Balance_Base],tblAcctSummary[Account_ID],A22)=0,NA(),SUMIFS(tblAcctSummary[Begin_Balance_Base],tblAcctSummary[Account_ID],A22)),0),0))
A23: =IFERROR(INDEX(tblAccounts[Account_ID],20),"") | B23: =IF(A23="","",IFERROR(XLOOKUP(A23,tblAccounts[Account_ID],tblAccounts[Account_Name],""),"")) | C23: =IF(A23="","",IFERROR(XLOOKUP(A23,tblAccounts[Account_ID],tblAccounts[Household_ID],""),"")) | D23: =IF(A23="","",IF(IFERROR(XLOOKUP(A23,tblAccounts[Account_ID],tblAccounts[Include],FALSE),FALSE),SUMIFS(tblAcctSummary[Begin_Balance_Base],tblAcctSummary[Account_ID],A23),0)) | E23: =IF(A23="","",IF(IFERROR(XLOOKUP(A23,tblAccounts[Account_ID],tblAccounts[Include],FALSE),FALSE),SUMIFS(tblAcctSummary[End_Balance_Base],tblAcctSummary[Account_ID],A23),0)) | F23: =IF(A23="","",IF(IFERROR(XLOOKUP(A23,tblAccounts[Account_ID],tblAccounts[Include],FALSE),FALSE),SUMIFS(tblAcctSummary[Net_Contrib_Base],tblAcctSummary[Account_ID],A23),0)) | G23: =IF(A23="","",IF(IFERROR(XLOOKUP(A23,tblAccounts[Account_ID],tblAccounts[Include],FALSE),FALSE),SUMIFS(tblAcctSummary[Income_Interest_Base],tblAcctSummary[Account_ID],A23),0)) | H23: =IF(A23="","",IF(IFERROR(XLOOKUP(A23,tblAccounts[Account_ID],tblAccounts[Include],FALSE),FALSE),SUMIFS(tblAcctSummary[Income_Dividends_Base],tblAcctSummary[Account_ID],A23),0)) | I23: =IF(A23="","",IF(IFERROR(XLOOKUP(A23,tblAccounts[Account_ID],tblAccounts[Include],FALSE),FALSE),SUMIFS(tblAcctSummary[Income_Other_Base],tblAcctSummary[Account_ID],A23),0)) | J23: =IF(A23="","",SUM(G23:I23)) | K23: =IF(A23="","",IF(IFERROR(XLOOKUP(A23,tblAccounts[Account_ID],tblAccounts[Include],FALSE),FALSE),SUMIFS(tblAcctSummary[Realized_GL_Base],tblAcctSummary[Account_ID],A23),0)) | L23: =IF(A23="","",IF(IFERROR(XLOOKUP(A23,tblAccounts[Account_ID],tblAccounts[Include],FALSE),FALSE),SUMIFS(tblAcctSummary[Fees_Base],tblAcctSummary[Account_ID],A23),0)) | M23: =IF(A23="","",IF(IFERROR(XLOOKUP(A23,tblAccounts[Account_ID],tblAccounts[Include],FALSE),FALSE),SUMIFS(tblAcctSummary[Taxes_Base],tblAcctSummary[Account_ID],A23),0)) | N23: =IF(A23="","",IF(IFERROR(XLOOKUP(A23,tblAccounts[Account_ID],tblAccounts[Include],FALSE),FALSE),IFERROR(SUMPRODUCT(tblAcctSummary[Return_Period],tblAcctSummary[Begin_Balance_Base],--(tblAcctSummary[Account_ID]=A23))/IF(SUMIFS(tblAcctSummary[Begin_Balance_Base],tblAcctSummary[Account_ID],A23)=0,NA(),SUMIFS(tblAcctSummary[Begin_Balance_Base],tblAcctSummary[Account_ID],A23)),0),0))
A24: =IFERROR(INDEX(tblAccounts[Account_ID],21),"") | B24: =IF(A24="","",IFERROR(XLOOKUP(A24,tblAccounts[Account_ID],tblAccounts[Account_Name],""),"")) | C24: =IF(A24="","",IFERROR(XLOOKUP(A24,tblAccounts[Account_ID],tblAccounts[Household_ID],""),"")) | D24: =IF(A24="","",IF(IFERROR(XLOOKUP(A24,tblAccounts[Account_ID],tblAccounts[Include],FALSE),FALSE),SUMIFS(tblAcctSummary[Begin_Balance_Base],tblAcctSummary[Account_ID],A24),0)) | E24: =IF(A24="","",IF(IFERROR(XLOOKUP(A24,tblAccounts[Account_ID],tblAccounts[Include],FALSE),FALSE),SUMIFS(tblAcctSummary[End_Balance_Base],tblAcctSummary[Account_ID],A24),0)) | F24: =IF(A24="","",IF(IFERROR(XLOOKUP(A24,tblAccounts[Account_ID],tblAccounts[Include],FALSE),FALSE),SUMIFS(tblAcctSummary[Net_Contrib_Base],tblAcctSummary[Account_ID],A24),0)) | G24: =IF(A24="","",IF(IFERROR(XLOOKUP(A24,tblAccounts[Account_ID],tblAccounts[Include],FALSE),FALSE),SUMIFS(tblAcctSummary[Income_Interest_Base],tblAcctSummary[Account_ID],A24),0)) | H24: =IF(A24="","",IF(IFERROR(XLOOKUP(A24,tblAccounts[Account_ID],tblAccounts[Include],FALSE),FALSE),SUMIFS(tblAcctSummary[Income_Dividends_Base],tblAcctSummary[Account_ID],A24),0)) | I24: =IF(A24="","",IF(IFERROR(XLOOKUP(A24,tblAccounts[Account_ID],tblAccounts[Include],FALSE),FALSE),SUMIFS(tblAcctSummary[Income_Other_Base],tblAcctSummary[Account_ID],A24),0)) | J24: =IF(A24="","",SUM(G24:I24)) | K24: =IF(A24="","",IF(IFERROR(XLOOKUP(A24,tblAccounts[Account_ID],tblAccounts[Include],FALSE),FALSE),SUMIFS(tblAcctSummary[Realized_GL_Base],tblAcctSummary[Account_ID],A24),0)) | L24: =IF(A24="","",IF(IFERROR(XLOOKUP(A24,tblAccounts[Account_ID],tblAccounts[Include],FALSE),FALSE),SUMIFS(tblAcctSummary[Fees_Base],tblAcctSummary[Account_ID],A24),0)) | M24: =IF(A24="","",IF(IFERROR(XLOOKUP(A24,tblAccounts[Account_ID],tblAccounts[Include],FALSE),FALSE),SUMIFS(tblAcctSummary[Taxes_Base],tblAcctSummary[Account_ID],A24),0)) | N24: =IF(A24="","",IF(IFERROR(XLOOKUP(A24,tblAccounts[Account_ID],tblAccounts[Include],FALSE),FALSE),IFERROR(SUMPRODUCT(tblAcctSummary[Return_Period],tblAcctSummary[Begin_Balance_Base],--(tblAcctSummary[Account_ID]=A24))/IF(SUMIFS(tblAcctSummary[Begin_Balance_Base],tblAcctSummary[Account_ID],A24)=0,NA(),SUMIFS(tblAcctSummary[Begin_Balance_Base],tblAcctSummary[Account_ID],A24)),0),0))
A25: =IFERROR(INDEX(tblAccounts[Account_ID],22),"") | B25: =IF(A25="","",IFERROR(XLOOKUP(A25,tblAccounts[Account_ID],tblAccounts[Account_Name],""),"")) | C25: =IF(A25="","",IFERROR(XLOOKUP(A25,tblAccounts[Account_ID],tblAccounts[Household_ID],""),"")) | D25: =IF(A25="","",IF(IFERROR(XLOOKUP(A25,tblAccounts[Account_ID],tblAccounts[Include],FALSE),FALSE),SUMIFS(tblAcctSummary[Begin_Balance_Base],tblAcctSummary[Account_ID],A25),0)) | E25: =IF(A25="","",IF(IFERROR(XLOOKUP(A25,tblAccounts[Account_ID],tblAccounts[Include],FALSE),FALSE),SUMIFS(tblAcctSummary[End_Balance_Base],tblAcctSummary[Account_ID],A25),0)) | F25: =IF(A25="","",IF(IFERROR(XLOOKUP(A25,tblAccounts[Account_ID],tblAccounts[Include],FALSE),FALSE),SUMIFS(tblAcctSummary[Net_Contrib_Base],tblAcctSummary[Account_ID],A25),0)) | G25: =IF(A25="","",IF(IFERROR(XLOOKUP(A25,tblAccounts[Account_ID],tblAccounts[Include],FALSE),FALSE),SUMIFS(tblAcctSummary[Income_Interest_Base],tblAcctSummary[Account_ID],A25),0)) | H25: =IF(A25="","",IF(IFERROR(XLOOKUP(A25,tblAccounts[Account_ID],tblAccounts[Include],FALSE),FALSE),SUMIFS(tblAcctSummary[Income_Dividends_Base],tblAcctSummary[Account_ID],A25),0)) | I25: =IF(A25="","",IF(IFERROR(XLOOKUP(A25,tblAccounts[Account_ID],tblAccounts[Include],FALSE),FALSE),SUMIFS(tblAcctSummary[Income_Other_Base],tblAcctSummary[Account_ID],A25),0)) | J25: =IF(A25="","",SUM(G25:I25)) | K25: =IF(A25="","",IF(IFERROR(XLOOKUP(A25,tblAccounts[Account_ID],tblAccounts[Include],FALSE),FALSE),SUMIFS(tblAcctSummary[Realized_GL_Base],tblAcctSummary[Account_ID],A25),0)) | L25: =IF(A25="","",IF(IFERROR(XLOOKUP(A25,tblAccounts[Account_ID],tblAccounts[Include],FALSE),FALSE),SUMIFS(tblAcctSummary[Fees_Base],tblAcctSummary[Account_ID],A25),0)) | M25: =IF(A25="","",IF(IFERROR(XLOOKUP(A25,tblAccounts[Account_ID],tblAccounts[Include],FALSE),FALSE),SUMIFS(tblAcctSummary[Taxes_Base],tblAcctSummary[Account_ID],A25),0)) | N25: =IF(A25="","",IF(IFERROR(XLOOKUP(A25,tblAccounts[Account_ID],tblAccounts[Include],FALSE),FALSE),IFERROR(SUMPRODUCT(tblAcctSummary[Return_Period],tblAcctSummary[Begin_Balance_Base],--(tblAcctSummary[Account_ID]=A25))/IF(SUMIFS(tblAcctSummary[Begin_Balance_Base],tblAcctSummary[Account_ID],A25)=0,NA(),SUMIFS(tblAcctSummary[Begin_Balance_Base],tblAcctSummary[Account_ID],A25)),0),0))
A26: =IFERROR(INDEX(tblAccounts[Account_ID],23),"") | B26: =IF(A26="","",IFERROR(XLOOKUP(A26,tblAccounts[Account_ID],tblAccounts[Account_Name],""),"")) | C26: =IF(A26="","",IFERROR(XLOOKUP(A26,tblAccounts[Account_ID],tblAccounts[Household_ID],""),"")) | D26: =IF(A26="","",IF(IFERROR(XLOOKUP(A26,tblAccounts[Account_ID],tblAccounts[Include],FALSE),FALSE),SUMIFS(tblAcctSummary[Begin_Balance_Base],tblAcctSummary[Account_ID],A26),0)) | E26: =IF(A26="","",IF(IFERROR(XLOOKUP(A26,tblAccounts[Account_ID],tblAccounts[Include],FALSE),FALSE),SUMIFS(tblAcctSummary[End_Balance_Base],tblAcctSummary[Account_ID],A26),0)) | F26: =IF(A26="","",IF(IFERROR(XLOOKUP(A26,tblAccounts[Account_ID],tblAccounts[Include],FALSE),FALSE),SUMIFS(tblAcctSummary[Net_Contrib_Base],tblAcctSummary[Account_ID],A26),0)) | G26: =IF(A26="","",IF(IFERROR(XLOOKUP(A26,tblAccounts[Account_ID],tblAccounts[Include],FALSE),FALSE),SUMIFS(tblAcctSummary[Income_Interest_Base],tblAcctSummary[Account_ID],A26),0)) | H26: =IF(A26="","",IF(IFERROR(XLOOKUP(A26,tblAccounts[Account_ID],tblAccounts[Include],FALSE),FALSE),SUMIFS(tblAcctSummary[Income_Dividends_Base],tblAcctSummary[Account_ID],A26),0)) | I26: =IF(A26="","",IF(IFERROR(XLOOKUP(A26,tblAccounts[Account_ID],tblAccounts[Include],FALSE),FALSE),SUMIFS(tblAcctSummary[Income_Other_Base],tblAcctSummary[Account_ID],A26),0)) | J26: =IF(A26="","",SUM(G26:I26)) | K26: =IF(A26="","",IF(IFERROR(XLOOKUP(A26,tblAccounts[Account_ID],tblAccounts[Include],FALSE),FALSE),SUMIFS(tblAcctSummary[Realized_GL_Base],tblAcctSummary[Account_ID],A26),0)) | L26: =IF(A26="","",IF(IFERROR(XLOOKUP(A26,tblAccounts[Account_ID],tblAccounts[Include],FALSE),FALSE),SUMIFS(tblAcctSummary[Fees_Base],tblAcctSummary[Account_ID],A26),0)) | M26: =IF(A26="","",IF(IFERROR(XLOOKUP(A26,tblAccounts[Account_ID],tblAccounts[Include],FALSE),FALSE),SUMIFS(tblAcctSummary[Taxes_Base],tblAcctSummary[Account_ID],A26),0)) | N26: =IF(A26="","",IF(IFERROR(XLOOKUP(A26,tblAccounts[Account_ID],tblAccounts[Include],FALSE),FALSE),IFERROR(SUMPRODUCT(tblAcctSummary[Return_Period],tblAcctSummary[Begin_Balance_Base],--(tblAcctSummary[Account_ID]=A26))/IF(SUMIFS(tblAcctSummary[Begin_Balance_Base],tblAcctSummary[Account_ID],A26)=0,NA(),SUMIFS(tblAcctSummary[Begin_Balance_Base],tblAcctSummary[Account_ID],A26)),0),0))
A27: =IFERROR(INDEX(tblAccounts[Account_ID],24),"") | B27: =IF(A27="","",IFERROR(XLOOKUP(A27,tblAccounts[Account_ID],tblAccounts[Account_Name],""),"")) | C27: =IF(A27="","",IFERROR(XLOOKUP(A27,tblAccounts[Account_ID],tblAccounts[Household_ID],""),"")) | D27: =IF(A27="","",IF(IFERROR(XLOOKUP(A27,tblAccounts[Account_ID],tblAccounts[Include],FALSE),FALSE),SUMIFS(tblAcctSummary[Begin_Balance_Base],tblAcctSummary[Account_ID],A27),0)) | E27: =IF(A27="","",IF(IFERROR(XLOOKUP(A27,tblAccounts[Account_ID],tblAccounts[Include],FALSE),FALSE),SUMIFS(tblAcctSummary[End_Balance_Base],tblAcctSummary[Account_ID],A27),0)) | F27: =IF(A27="","",IF(IFERROR(XLOOKUP(A27,tblAccounts[Account_ID],tblAccounts[Include],FALSE),FALSE),SUMIFS(tblAcctSummary[Net_Contrib_Base],tblAcctSummary[Account_ID],A27),0)) | G27: =IF(A27="","",IF(IFERROR(XLOOKUP(A27,tblAccounts[Account_ID],tblAccounts[Include],FALSE),FALSE),SUMIFS(tblAcctSummary[Income_Interest_Base],tblAcctSummary[Account_ID],A27),0)) | H27: =IF(A27="","",IF(IFERROR(XLOOKUP(A27,tblAccounts[Account_ID],tblAccounts[Include],FALSE),FALSE),SUMIFS(tblAcctSummary[Income_Dividends_Base],tblAcctSummary[Account_ID],A27),0)) | I27: =IF(A27="","",IF(IFERROR(XLOOKUP(A27,tblAccounts[Account_ID],tblAccounts[Include],FALSE),FALSE),SUMIFS(tblAcctSummary[Income_Other_Base],tblAcctSummary[Account_ID],A27),0)) | J27: =IF(A27="","",SUM(G27:I27)) | K27: =IF(A27="","",IF(IFERROR(XLOOKUP(A27,tblAccounts[Account_ID],tblAccounts[Include],FALSE),FALSE),SUMIFS(tblAcctSummary[Realized_GL_Base],tblAcctSummary[Account_ID],A27),0)) | L27: =IF(A27="","",IF(IFERROR(XLOOKUP(A27,tblAccounts[Account_ID],tblAccounts[Include],FALSE),FALSE),SUMIFS(tblAcctSummary[Fees_Base],tblAcctSummary[Account_ID],A27),0)) | M27: =IF(A27="","",IF(IFERROR(XLOOKUP(A27,tblAccounts[Account_ID],tblAccounts[Include],FALSE),FALSE),SUMIFS(tblAcctSummary[Taxes_Base],tblAcctSummary[Account_ID],A27),0)) | N27: =IF(A27="","",IF(IFERROR(XLOOKUP(A27,tblAccounts[Account_ID],tblAccounts[Include],FALSE),FALSE),IFERROR(SUMPRODUCT(tblAcctSummary[Return_Period],tblAcctSummary[Begin_Balance_Base],--(tblAcctSummary[Account_ID]=A27))/IF(SUMIFS(tblAcctSummary[Begin_Balance_Base],tblAcctSummary[Account_ID],A27)=0,NA(),SUMIFS(tblAcctSummary[Begin_Balance_Base],tblAcctSummary[Account_ID],A27)),0),0))
A28: =IFERROR(INDEX(tblAccounts[Account_ID],25),"") | B28: =IF(A28="","",IFERROR(XLOOKUP(A28,tblAccounts[Account_ID],tblAccounts[Account_Name],""),"")) | C28: =IF(A28="","",IFERROR(XLOOKUP(A28,tblAccounts[Account_ID],tblAccounts[Household_ID],""),"")) | D28: =IF(A28="","",IF(IFERROR(XLOOKUP(A28,tblAccounts[Account_ID],tblAccounts[Include],FALSE),FALSE),SUMIFS(tblAcctSummary[Begin_Balance_Base],tblAcctSummary[Account_ID],A28),0)) | E28: =IF(A28="","",IF(IFERROR(XLOOKUP(A28,tblAccounts[Account_ID],tblAccounts[Include],FALSE),FALSE),SUMIFS(tblAcctSummary[End_Balance_Base],tblAcctSummary[Account_ID],A28),0)) | F28: =IF(A28="","",IF(IFERROR(XLOOKUP(A28,tblAccounts[Account_ID],tblAccounts[Include],FALSE),FALSE),SUMIFS(tblAcctSummary[Net_Contrib_Base],tblAcctSummary[Account_ID],A28),0)) | G28: =IF(A28="","",IF(IFERROR(XLOOKUP(A28,tblAccounts[Account_ID],tblAccounts[Include],FALSE),FALSE),SUMIFS(tblAcctSummary[Income_Interest_Base],tblAcctSummary[Account_ID],A28),0)) | H28: =IF(A28="","",IF(IFERROR(XLOOKUP(A28,tblAccounts[Account_ID],tblAccounts[Include],FALSE),FALSE),SUMIFS(tblAcctSummary[Income_Dividends_Base],tblAcctSummary[Account_ID],A28),0)) | I28: =IF(A28="","",IF(IFERROR(XLOOKUP(A28,tblAccounts[Account_ID],tblAccounts[Include],FALSE),FALSE),SUMIFS(tblAcctSummary[Income_Other_Base],tblAcctSummary[Account_ID],A28),0)) | J28: =IF(A28="","",SUM(G28:I28)) | K28: =IF(A28="","",IF(IFERROR(XLOOKUP(A28,tblAccounts[Account_ID],tblAccounts[Include],FALSE),FALSE),SUMIFS(tblAcctSummary[Realized_GL_Base],tblAcctSummary[Account_ID],A28),0)) | L28: =IF(A28="","",IF(IFERROR(XLOOKUP(A28,tblAccounts[Account_ID],tblAccounts[Include],FALSE),FALSE),SUMIFS(tblAcctSummary[Fees_Base],tblAcctSummary[Account_ID],A28),0)) | M28: =IF(A28="","",IF(IFERROR(XLOOKUP(A28,tblAccounts[Account_ID],tblAccounts[Include],FALSE),FALSE),SUMIFS(tblAcctSummary[Taxes_Base],tblAcctSummary[Account_ID],A28),0)) | N28: =IF(A28="","",IF(IFERROR(XLOOKUP(A28,tblAccounts[Account_ID],tblAccounts[Include],FALSE),FALSE),IFERROR(SUMPRODUCT(tblAcctSummary[Return_Period],tblAcctSummary[Begin_Balance_Base],--(tblAcctSummary[Account_ID]=A28))/IF(SUMIFS(tblAcctSummary[Begin_Balance_Base],tblAcctSummary[Account_ID],A28)=0,NA(),SUMIFS(tblAcctSummary[Begin_Balance_Base],tblAcctSummary[Account_ID],A28)),0),0))
